Workbook

Sheet README
A1: Nginx Server Documentation - leadowserver
A2: Source: sudo nginx -T on 2026-10-01 (active config only; commented-out lines and backup files are excluded)
A4: Summary
A5: Total routes documented | B5: =COUNTA('Domain Map'!$B$2:$B$107) -> 106
A6: Unique domain entries | B6: =SUMPRODUCT(1/COUNTIF('Domain Map'!$B$2:$B$107,'Domain Map'!$B$2:$B$107)) -> 39
A7: Proxy routes | B7: =COUNTIF('Domain Map'!$F$2:$F$107,"Proxy") -> 63
A8: Static-site routes | B8: =COUNTIF('Domain Map'!$F$2:$F$107,"Static") -> 25
A9: Redirect / return routes | B9: =COUNTIF('Domain Map'!$F$2:$F$107,"Redirect")+COUNTIF('Domain Map'!$F$2:$F$107,"Return") -> 17
A10: Listening HTTP ports | B10: =COUNTIF('Port Summary'!$B$2:$B$20,"HTTP") -> 13
A11: Listening TCP stream ports | B11: =COUNTIF('Port Summary'!$B$2:$B$20,"Stream (TCP)") -> 6
A12: Open issues to review | B12: =COUNTA('Issues & Checks'!$C$2:$C$13) -> 12
A14: Sheets
A15: Domain Map | B15: Main table: every domain, port, path and where it goes. Use the filter arrows to search by domain, port or backend.
A16: Port Summary | B16: Every port nginx listens on and which domains use it.
A17: Backends | B17: Every backend IP:port nginx forwards to and which domains use it.
A18: Config Files | B18: Which file in /etc/nginx/conf.d holds what; backup files that are not loaded.
A19: Issues & Checks | B19: Possible conflicts and things to verify, with the command to run.
A21: Action colours (Domain Map)
A22: Proxy | B22: Forwarded to a backend app
A23: Static | B23: Files served directly by nginx
A24: Redirect | B24: HTTP redirect (301/302)
A25: Status | B25: nginx monitoring page
A27: Note: values marked '(not captured)' were not in the output you sent. See 'Issues & Checks' for the command to fill them in.

Sheet Domain Map
A1: # | B1: Domain | C1: Port | D1: Protocol | E1: Path | F1: Action | G1: Target / Backend | H1: Backend Host | I1: Backend Port | J1: Config File (/etc/nginx/conf.d/) | K1: Notes
A2: 1 | B2: abg.leadows.com | C2: 443 | D2: HTTPS | E2: / | F2: Proxy | G2: http://10.0.0.100:8090 | H2: 10.0.0.100 | I2: 8090 | J2: abg.leadows.conf
A3: 2 | B3: abg.leadows.com | C3: 80 | D3: HTTP | E3: / | F3: Redirect | G3: 301 -> https://abg.leadows.com | J3: abg.leadows.conf
A4: 3 | B4: akhbar.mahdibagh.net | C4: 443 | D4: HTTPS | E4: / | F4: Proxy | G4: upstream: publisher | J4: akhbar.mahdibagh.net.conf | K4: Upstream address not captured
A5: 4 | B5: akhbar.mahdibagh.net | C5: 80 | D5: HTTP | E5: / | F5: Redirect | G5: 301 -> HTTPS (otherwise 404) | J5: akhbar.mahdibagh.net.conf
A6: 5 | B6: app.schoolsecurity.uz | C6: 10181 | D6: HTTP | E6: / | F6: Static | G6: root /usr/share/nginx/html/webapp.schoolsecurity.uz | J6: app.schoolsecurity.uz.conf | K6: Plain HTTP (SSL block commented out)
A7: 6 | B7: ban.leadows.com (server_name _) | C7: 10081 | D7: HTTP | E7: /api/ | F7: Proxy | G7: http://127.0.0.1:4100 | H7: localhost | I7: 4100 | J7: ban.leadows.com.conf | K7: Catch-all server_name _ ; plain HTTP (SSL commented out); also listens on IPv6
A8: 7 | B8: ban.leadows.com (server_name _) | C8: 10081 | D8: HTTP | E8: /files/ | F8: Proxy | G8: http://127.0.0.1:4100/api/files/ | H8: localhost | I8: 4100 | J8: ban.leadows.com.conf | K8: Legacy image URLs (pre S3 API)
A9: 8 | B9: ban.leadows.com (server_name _) | C9: 10081 | D9: HTTP | E9: /assets/ | F9: Static | G9: root .../ban-web-app/apps/web/dist (cache 1y) | J9: ban.leadows.com.conf
A10: 9 | B10: ban.leadows.com (server_name _) | C10: 10081 | D10: HTTP | E10: /sw.js | F10: Static | G10: root .../ban-web-app/apps/web/dist (no-cache) | J10: ban.leadows.com.conf
A11: 10 | B11: ban.leadows.com (server_name _) | C11: 10081 | D11: HTTP | E11: /manifest.webmanifest | F11: Static | G11: root .../ban-web-app/apps/web/dist (no-cache) | J11: ban.leadows.com.conf
A12: 11 | B12: ban.leadows.com (server_name _) | C12: 10081 | D12: HTTP | E12: / | F12: Static | G12: root /dataDrive/BusinessAllianceNetwork/ban-web-app/apps/web/dist (SPA) | J12: ban.leadows.com.conf | K12: client_max_body_size 6m
A13: 12 | B13: books.leadows.com | C13: 443 | D13: HTTPS | E13: /live/project/ | F13: Proxy | G13: (target not captured) | J13: books.leadows.conf | K13: Check conf for target
A14: 13 | B14: books.leadows.com | C14: 443 | D14: HTTPS | E14: /api/ | F14: Proxy | G14: http://127.0.0.1:3001 | H14: localhost | I14: 3001 | J14: books.leadows.conf
A15: 14 | B15: books.leadows.com | C15: 443 | D15: HTTPS | E15: / | F15: Proxy | G15: http://127.0.0.1:6875 | H15: localhost | I15: 6875 | J15: books.leadows.conf
A16: 15 | B16: bugs.leadows.com | C16: 443 | D16: HTTPS | E16: / | F16: Proxy | G16: http://10.0.0.100:8082/ | H16: 10.0.0.100 | I16: 8082 | J16: bugs.leadows.com.conf | K16: Bugzilla; max upload 20M
A17: 16 | B17: demoshop.leadows.com | C17: 443 | D17: HTTPS | E17: / | F17: Proxy | G17: http://localhost:8555 | H17: localhost | I17: 8555 | J17: demoshop.leadows.com.conf | K17: Rate limit zone php_limit (burst 25); max upload 500M; WebSocket upgrade
A18: 17 | B18: demoshop.leadows.com | C18: 443 | D18: HTTPS | E18: /phpmyadmin/ | F18: Proxy | G18: http://127.0.0.1:8556/ | H18: localhost | I18: 8556 | J18: demoshop.leadows.com.conf | K18: phpMyAdmin
A19: 18 | B19: demoshop.leadows.com | C19: 80 | D19: HTTP | E19: / | F19: Redirect | G19: 301 -> HTTPS (otherwise 404) | J19: demoshop.leadows.com.conf | K19: Blocks query strings like ?a=123 with 403
A20: 19 | B20: docs.mahdibagh.org | C20: 443 | D20: HTTPS | E20: / | F20: Proxy | G20: http://192.168.1.222:82/ | H20: 192.168.1.222 | I20: 82 | J20: docs.mahdibagh.org.conf | K20: Max upload 500M
A21: 20 | B21: docs.mahdibagh.org | C21: 443 | D21: HTTPS | E21: /ns | F21: Return | G21: 301 -> / | J21: docs.mahdibagh.org.conf
A22: 21 | B22: doks.leadows.com | C22: 80 | D22: HTTP | E22: / | F22: Redirect | G22: 301 -> HTTPS | J22: doks.leadows.com.conf
A23: 22 | B23: doks.leadows.com | C23: 443 | D23: HTTPS | E23: / | F23: Proxy | G23: http://192.168.1.221:8180 | H23: 192.168.1.221 | I23: 8180 | J23: doks.leadows.com.conf | K23: Max upload 100m
A24: 23 | B24: doks.leadows.com | C24: 443 | D24: HTTPS | E24: /ds-vpath/ | F24: Proxy | G24: http://192.168.1.221:8180/ds-vpath/ | H24: 192.168.1.221 | I24: 8180 | J24: doks.leadows.com.conf
A25: 24 | B25: doks.leadows.com | C25: 443 | D25: HTTPS | E25: /controlpanel/ | F25: Proxy | G25: http://192.168.1.221:8180/controlpanel/ | H25: 192.168.1.221 | I25: 8180 | J25: doks.leadows.com.conf
A26: 25 | B26: emr.mahdibagh.org | C26: 443 | D26: HTTPS | E26: / | F26: Proxy | G26: http://192.168.1.222:8080 | H26: 192.168.1.222 | I26: 8080 | J26: emr.mahdibagh.org.conf | K26: Max upload 50M
A27: 26 | B27: emr.mahdibagh.org | C27: 80 | D27: HTTP | E27: / | F27: Redirect | G27: 301 -> HTTPS | J27: emr.mahdibagh.org.conf
A28: 27 | B28: ems-staging.leadows.com | C28: 443 | D28: HTTPS | E28: / , /admin/ , /favicon.ico | F28: Static | G28: root /usr/share/nginx/html/ems-staging.leadows.com | J28: ems-staging.leadows.com.conf
A29: 28 | B29: ems-staging.leadows.com | C29: 443 | D29: HTTPS | E29: /api/ | F29: Proxy | G29: http://10.0.0.100:5050 | H29: 10.0.0.100 | I29: 5050 | J29: ems-staging.leadows.com.conf
A30: 29 | B30: ems.leadows.com | C30: 443 | D30: HTTPS | E30: / , /admin/ , /favicon.ico | F30: Static | G30: root /usr/share/nginx/html/ems.leadows.com | J30: ems.leadows.com.conf
A31: 30 | B31: ems.leadows.com | C31: 443 | D31: HTTPS | E31: /app | F31: Redirect | G31: 302 -> App Store / Play Store (else https://ems.leadows.com/) | J31: ems.leadows.com.conf | K31: Store links look like a placeholder (Airbnb app IDs) - verify
A32: 31 | B32: ems.leadows.com | C32: 443 | D32: HTTPS | E32: /api/ | F32: Proxy | G32: http://10.0.0.100:5000 | H32: 10.0.0.100 | I32: 5000 | J32: ems.leadows.com.conf
A33: 32 | B33: ems.leadows.com | C33: 3021 | D33: HTTPS | E33: / | F33: Proxy | G33: http://10.0.0.100:5000/ | H33: 10.0.0.100 | I33: 5000 | J33: ems.leadows.com.conf | K33: Alternate HTTPS port
A34: 33 | B34: ems.leadows.com | C34: 3022 | D34: HTTPS | E34: / , /favicon.ico | F34: Static | G34: root /usr/share/nginx/html/sa.ems.leadows.com | J34: ems.leadows.com.conf | K34: Super-admin front end
A35: 34 | B35: hub.leadows.com | C35: 443 | D35: HTTPS | E35: / | F35: Static | G35: root /usr/share/nginx/html/twine_frontend | J35: hub.leadows.com.conf
A36: 35 | B36: khabar.mahdibagh.net | C36: 80 | D36: HTTP | E36: / | F36: Redirect | G36: 301 -> HTTPS | J36: khabar.mahdibagh.net.conf
A37: 36 | B37: khabar.mahdibagh.net | C37: 443 | D37: HTTPS | E37: / | F37: Proxy | G37: upstream: superdesk_client | J37: khabar.mahdibagh.net.conf | K37: Superdesk; upstream address not captured; HTTP/2; max upload 500M
A38: 37 | B38: khabar.mahdibagh.net | C38: 443 | D38: HTTPS | E38: /api/v2/ | F38: Proxy | G38: upstream: publisher-server | J38: khabar.mahdibagh.net.conf | K38: Upstream address not captured
A39: 38 | B39: khabar.mahdibagh.net | C39: 443 | D39: HTTPS | E39: /media/ | F39: Proxy | G39: upstream: publisher-server | J39: khabar.mahdibagh.net.conf | K39: Upstream address not captured
A40: 39 | B40: khabar.mahdibagh.net | C40: 443 | D40: HTTPS | E40: /api/ | F40: Proxy | G40: upstream: superdesk_server | J40: khabar.mahdibagh.net.conf | K40: Upstream address not captured
...

Sheet Port Summary
A1: Port | B1: Layer | C1: Protocol | D1: Domains / Services using this port | E1: Routes in Domain Map | F1: Purpose
A2: 80 | B2: HTTP | C2: HTTP | D2: abg.leadows.com, akhbar.mahdibagh.net, demoshop.leadows.com, doks.leadows.com, emr.mahdibagh.org, khabar.mahdibagh.net, www.mahdibagh.org, mbapp.mahdibagh.net, rag.leadows.com, www.schoolsecurity.uz, schoolsecurity.uz, tasks.leadows.com, training.leadows.com, (default server) | E2: =COUNTIF('Domain Map'!$C$2:$C$107,A2) -> 15 | F2: HTTP - redirects to HTTPS (or 404)
A3: 443 | B3: HTTP | C3: HTTPS | D3: abg.leadows.com, akhbar.mahdibagh.net, books.leadows.com, bugs.leadows.com, demoshop.leadows.com, docs.mahdibagh.org, doks.leadows.com, emr.mahdibagh.org, ems-staging.leadows.com, ems.leadows.com, hub.leadows.com, khabar.mahdibagh.net, leadowserp.com, www.leadowserp.com, leadowserp.leadows.com, www.mahdibagh.org, mbyc.mahdibagh.org, mbapp.mahdibagh.net, mbc.leadows.com, myneuron.leadows.com, primary.leadowserp.com, publisher.khabar.mahdibagh.net, punekar.leadows.com, rag.leadows.com, restaurant.leadows.com, staging.leadowserp.com, tasks.leadows.com, train.leadows.com, training.leadows.com, warehouse.leadows.com | E3: =COUNTIF('Domain Map'!$C$2:$C$107,A3) -> 64 | F3: HTTPS - main public port
A4: 3009 | B4: HTTP | C4: HTTPS | D4: leadowserp.leadows.com, mbc.leadows.com, staging.leadowserp.com | E4: =COUNTIF('Domain Map'!$C$2:$C$107,A4) -> 3 | F4: Alternate HTTPS port (ERP apps)
A5: 3021 | B5: HTTP | C5: HTTPS | D5: ems.leadows.com | E5: =COUNTIF('Domain Map'!$C$2:$C$107,A5) -> 1 | F5: Alternate HTTPS port (ems.leadows.com)
A6: 3022 | B6: HTTP | C6: HTTPS | D6: ems.leadows.com | E6: =COUNTIF('Domain Map'!$C$2:$C$107,A6) -> 1 | F6: Alternate HTTPS port (ems super-admin)
A7: 4000 | B7: HTTP | C7: HTTPS | D7: myneuron.leadows.com, primary.leadowserp.com, punekar.leadows.com | E7: =COUNTIF('Domain Map'!$C$2:$C$107,A7) -> 3 | F7: Alternate HTTPS port (apps proxied to backends)
A8: 4020 | B8: HTTP | C8: HTTPS | D8: warehouse.leadows.com | E8: =COUNTIF('Domain Map'!$C$2:$C$107,A8) -> 1 | F8: Alternate HTTPS port (warehouse backend)
A9: 8080 | B9: HTTP | C9: HTTP | D9: localhost | E9: =COUNTIF('Domain Map'!$C$2:$C$107,A9) -> 1 | F9: Local nginx monitoring (stub_status)
A10: 10080 | B10: HTTP | C10: HTTP | D10: schoolbus.leadows.com | E10: =COUNTIF('Domain Map'!$C$2:$C$107,A10) -> 4 | F10: Plain HTTP - school bus app
A11: 10081 | B11: HTTP | C11: HTTP | D11: ban.leadows.com (server_name _) | E11: =COUNTIF('Domain Map'!$C$2:$C$107,A11) -> 6 | F11: Plain HTTP - BAN web app (catch-all)
A12: 10180 | B12: HTTP | C12: HTTP | D12: api.schoolsecurity.uz | E12: =COUNTIF('Domain Map'!$C$2:$C$107,A12) -> 4 | F12: Plain HTTP - school security API
A13: 10181 | B13: HTTP | C13: HTTP | D13: app.schoolsecurity.uz | E13: =COUNTIF('Domain Map'!$C$2:$C$107,A13) -> 1 | F13: Plain HTTP - school security web app
A14: 28096 | B14: HTTP | C14: HTTP | D14: mm.leadows.com (server_name _) | E14: =COUNTIF('Domain Map'!$C$2:$C$107,A14) -> 1 | F14: Plain HTTP - media server (catch-all)
A15: 7001 | B15: Stream (TCP) | C15: TCP | D15: Redis cluster node -> 192.168.1.221:37001 | redis_cluster.conf.stream (IP whitelist: redis_whitelist.conf) | E15: - | F15: Raw TCP proxy (not HTTP)
A16: 7002 | B16: Stream (TCP) | C16: TCP | D16: Redis cluster node -> 192.168.1.221:37002 | redis_cluster.conf.stream (IP whitelist: redis_whitelist.conf) | E16: - | F16: Raw TCP proxy (not HTTP)
A17: 7003 | B17: Stream (TCP) | C17: TCP | D17: Redis cluster node -> 192.168.1.221:37003 | redis_cluster.conf.stream (IP whitelist: redis_whitelist.conf) | E17: - | F17: Raw TCP proxy (not HTTP)
A18: 60007 | B18: Stream (TCP) | C18: TCP | D18: MongoDB cluster (upstream mongo_cluster) | nginx.conf (stream block) | E18: - | F18: Raw TCP proxy (not HTTP)
A19: 60008 | B19: Stream (TCP) | C19: TCP | D19: MongoDB cluster (upstream mongo_cluster) | nginx.conf (stream block) | E19: - | F19: Raw TCP proxy (not HTTP)
A20: 60009 | B20: Stream (TCP) | C20: TCP | D20: MongoDB cluster (upstream mongo_cluster) | nginx.conf (stream block) | E20: - | F20: Raw TCP proxy (not HTTP)

Sheet Backends
A1: Backend Host | B1: Backend Port | C1: Used By (domain + path) | D1: Routes | E1: Notes
A2: localhost | B2: 3001 | C2: books.leadows.com/api/ | D2: =COUNTIFS('Domain Map'!$H$2:$H$107,A2,'Domain Map'!$I$2:$I$107,B2) -> 1 | E2: Runs on this nginx server itself
A3: localhost | B3: 4100 | C3: ban.leadows.com (server_name _)/api/ ban.leadows.com (server_name _)/files/ | D3: =COUNTIFS('Domain Map'!$H$2:$H$107,A3,'Domain Map'!$I$2:$I$107,B3) -> 2 | E3: Runs on this nginx server itself
A4: localhost | B4: 6875 | C4: books.leadows.com | D4: =COUNTIFS('Domain Map'!$H$2:$H$107,A4,'Domain Map'!$I$2:$I$107,B4) -> 1 | E4: Runs on this nginx server itself
A5: localhost | B5: 7000 | C5: restaurant.leadows.com/task... | D5: =COUNTIFS('Domain Map'!$H$2:$H$107,A5,'Domain Map'!$I$2:$I$107,B5) -> 1 | E5: Runs on this nginx server itself
A6: localhost | B6: 8020 | C6: restaurant.leadows.com/api/ | D6: =COUNTIFS('Domain Map'!$H$2:$H$107,A6,'Domain Map'!$I$2:$I$107,B6) -> 1 | E6: Runs on this nginx server itself
A7: localhost | B7: 8078 | C7: schoolbus.leadows.com/api/ | D7: =COUNTIFS('Domain Map'!$H$2:$H$107,A7,'Domain Map'!$I$2:$I$107,B7) -> 1 | E7: Runs on this nginx server itself
A8: localhost | B8: 8080 | C8: restaurant.leadows.com/rag/api/ | D8: =COUNTIFS('Domain Map'!$H$2:$H$107,A8,'Domain Map'!$I$2:$I$107,B8) -> 1 | E8: Runs on this nginx server itself
A9: localhost | B9: 8088 | C9: schoolbus.leadows.com/geo/ | D9: =COUNTIFS('Domain Map'!$H$2:$H$107,A9,'Domain Map'!$I$2:$I$107,B9) -> 1 | E9: Runs on this nginx server itself
A10: localhost | B10: 8555 | C10: demoshop.leadows.com | D10: =COUNTIFS('Domain Map'!$H$2:$H$107,A10,'Domain Map'!$I$2:$I$107,B10) -> 1 | E10: Runs on this nginx server itself
A11: localhost | B11: 8556 | C11: demoshop.leadows.com/phpmyadmin/ | D11: =COUNTIFS('Domain Map'!$H$2:$H$107,A11,'Domain Map'!$I$2:$I$107,B11) -> 1 | E11: Runs on this nginx server itself
A12: localhost | B12: 9000 | C12: restaurant.leadows.com/rag/ api.schoolsecurity.uz/api/ | D12: =COUNTIFS('Domain Map'!$H$2:$H$107,A12,'Domain Map'!$I$2:$I$107,B12) -> 2 | E12: Runs on this nginx server itself
A13: localhost | B13: 9001 | C13: api.schoolsecurity.uz/geo/ | D13: =COUNTIFS('Domain Map'!$H$2:$H$107,A13,'Domain Map'!$I$2:$I$107,B13) -> 1 | E13: Runs on this nginx server itself
... A15: localhost | B15: 9020 | C15: warehouse.leadows.com | D15: =COUNTIFS('Domain Map'!$H$2:$H$107,A15,'Domain Map'!$I$2:$I$107,B15) -> 1 | E15: Runs on this nginx server itself
A16: $jellyfin (variable) | B16: 8096 | C16: train.leadows.com train.leadows.com/socket | D16: =COUNTIFS('Domain Map'!$H$2:$H$107,A16,'Domain Map'!$I$2:$I$107,B16) -> 2
A17: 10.0.0.100 | B17: 3010 | C17: leadowserp.com, www.leadowserp.com leadowserp.leadows.com mbc.leadows.com/api/ mbc.leadows.com | D17: =COUNTIFS('Domain Map'!$H$2:$H$107,A17,'Domain Map'!$I$2:$I$107,B17) -> 4 | E17: Backend server A
A18: 10.0.0.100 | B18: 5000 | C18: ems.leadows.com/api/ ems.leadows.com | D18: =COUNTIFS('Domain Map'!$H$2:$H$107,A18,'Domain Map'!$I$2:$I$107,B18) -> 2 | E18: Backend server A
A19: 10.0.0.100 | B19: 5050 | C19: ems-staging.leadows.com/api/ | D19: =COUNTIFS('Domain Map'!$H$2:$H$107,A19,'Domain Map'!$I$2:$I$107,B19) -> 1 | E19: Backend server A
A20: 10.0.0.100 | B20: 8082 | C20: bugs.leadows.com | D20: =COUNTIFS('Domain Map'!$H$2:$H$107,A20,'Domain Map'!$I$2:$I$107,B20) -> 1 | E20: Backend server A
A21: 10.0.0.100 | B21: 8090 | C21: abg.leadows.com | D21: =COUNTIFS('Domain Map'!$H$2:$H$107,A21,'Domain Map'!$I$2:$I$107,B21) -> 1 | E21: Backend server A
A22: 10.0.0.100 | B22: 8333 | C22: schoolbus.leadows.com/s3/ api.schoolsecurity.uz/s3/ | D22: =COUNTIFS('Domain Map'!$H$2:$H$107,A22,'Domain Map'!$I$2:$I$107,B22) -> 2 | E22: Backend server A
A23: 10.0.0.100 | B23: 8989 | C23: tasks.leadows.com | D23: =COUNTIFS('Domain Map'!$H$2:$H$107,A23,'Domain Map'!$I$2:$I$107,B23) -> 1 | E23: Backend server A
A24: 10.0.0.100 | B24: 9011 | C24: punekar.leadows.com | D24: =COUNTIFS('Domain Map'!$H$2:$H$107,A24,'Domain Map'!$I$2:$I$107,B24) -> 1 | E24: Backend server A
A25: 10.0.0.200 | B25: 3100 | C25: mbapp.mahdibagh.net/api | D25: =COUNTIFS('Domain Map'!$H$2:$H$107,A25,'Domain Map'!$I$2:$I$107,B25) -> 1 | E25: Backend server B
A26: 10.0.0.200 | B26: 8080 | C26: mbapp.mahdibagh.net | D26: =COUNTIFS('Domain Map'!$H$2:$H$107,A26,'Domain Map'!$I$2:$I$107,B26) -> 1 | E26: Backend server B
A27: 10.0.0.200 | B27: 8096 | C27: mm.leadows.com (server_name _) | D27: =COUNTIFS('Domain Map'!$H$2:$H$107,A27,'Domain Map'!$I$2:$I$107,B27) -> 1 | E27: Backend server B
A28: 10.0.0.200 | B28: 8786 | C28: www.mahdibagh.org/administrator/ www.mahdibagh.org~ \.php$ (PHP files) www.mahdibagh.org | D28: =COUNTIFS('Domain Map'!$H$2:$H$107,A28,'Domain Map'!$I$2:$I$107,B28) -> 3 | E28: Backend server B
... A35: 192.168.1.222 | B35: 8787 | C35: mbyc.mahdibagh.org/administrator/ mbyc.mahdibagh.org~ \.php$ (PHP files) mbyc.mahdibagh.org | D35: =COUNTIFS('Domain Map'!$H$2:$H$107,A35,'Domain Map'!$I$2:$I$107,B35) -> 3 | E35: Backend server D (LAN)

Sheet Config Files
A1: Config File | B1: Status | C1: Domains / Purpose
A2: abg.leadows.conf | B2: Active (loaded) | C2: abg.leadows.com
A3: akhbar.mahdibagh.net.conf | B3: Active (loaded) | C3: akhbar.mahdibagh.net
A4: app.schoolsecurity.uz.conf | B4: Active (loaded) | C4: app.schoolsecurity.uz
A5: ban.leadows.com.conf | B5: Active (loaded) | C5: ban.leadows.com (server_name _)
A6: books.leadows.conf | B6: Active (loaded) | C6: books.leadows.com
A7: bugs.leadows.com.conf | B7: Active (loaded) | C7: bugs.leadows.com
A8: demoshop.leadows.com.conf | B8: Active (loaded) | C8: demoshop.leadows.com
A9: docs.mahdibagh.org.conf | B9: Active (loaded) | C9: docs.mahdibagh.org
A10: doks.leadows.com.conf | B10: Active (loaded) | C10: doks.leadows.com
A11: emr.mahdibagh.org.conf | B11: Active (loaded) | C11: emr.mahdibagh.org
A12: ems-staging.leadows.com.conf | B12: Active (loaded) | C12: ems-staging.leadows.com
... A49: ems-staging.leadows.com.conf.save | B49: Backup - NOT loaded | C49: Ignored by nginx (extension is not .conf). Safe to archive or delete.

Sheet Issues & Checks
A1: # | B1: Priority | C1: Item | D1: What was seen | E1: What to check / do
A2: 1 | B2: High | C2: Port 8080 used twice | D2: nginx stub_status listens on 8080, and restaurant.leadows.com /rag/api/ proxies to 127.0.0.1:8080 (RAG backend). | E2: Run: sudo ss -tlnp | grep :8080 - if both are expected, move stub_status to a different port (e.g. 8081).
A3: 2 | B3: High | C3: Local port 9000 used twice | D3: restaurant /rag/ -> 127.0.0.1:9000 (Vite) and api.schoolsecurity.uz /api/ -> 127.0.0.1:9000. | E3: Run: sudo ss -tlnp | grep :9000 - confirm which app really owns it and give the other app its own port.
A4: 3 | B4: High | C4: Database ports exposed via nginx | D4: Redis (7001-7003) and MongoDB (60007-60009) are published as TCP stream ports. | E4: Confirm firewall / redis_whitelist.conf restricts who can connect. Check that the whitelist covers the Mongo ports too.
A5: 4 | B5: Medium | C5: Public plain-HTTP ports | D5: 10080, 10081, 10180, 10181 and 28096 have no SSL in nginx. | E5: Confirm TLS is handled elsewhere (e.g. another proxy/CDN) or add SSL if exposed to the internet.
A6: 5 | B6: Medium | C6: schoolsecurity.uz has no HTTPS block | D6: Port 80 redirects to https://schoolsecurity.uz, but no 443 server for that domain appeared in the output. | E6: Run: sudo nginx -T | grep -n 'schoolsecurity.uz' to confirm the 443 block exists.
A7: 6 | B7: Medium | C7: Upstream/variable addresses not captured | D7: Upstreams: publisher, superdesk_client/server/ws/capi, publisher-server, media_proxy, helix_backend, rag_backend, doc_backend, mongo_cluster; variable $jellyfin. | E7: Run: sudo nginx -T 2>/dev/null | grep -E -A6 '^\s*upstream|^\s*map ' and send the output so the sheet can be completed.
A8: 7 | B8: Medium | C8: Missing target | D8: books.leadows.com /live/project/ target not captured. | E8: Run: sudo grep -A6 '/live/project/' /etc/nginx/conf.d/books.leadows.conf
A9: 8 | B9: Low | C9: Catch-all server_name _ on custom ports | D9: ban (10081) and mm (28096) answer to any host name on those ports. | E9: Acceptable, but any request to server-IP:port reaches the app. Set a real server_name if needed.
A10: 9 | B10: Low | C10: Shared alternate ports | D10: 3009, 4000 are shared by several domains. | E10: Works through SNI (name-based). Clients without SNI may get the first server's certificate.
A11: 10 | B11: Low | C11: Placeholder app-store links | D11: ems.leadows.com /app redirects to Airbnb app-store links. | E11: Replace with your real app links when ready.
A12: 11 | B12: Low | C12: Backup files in conf.d | D12: 10 .bak / .save files exist (see Config Files sheet). | E12: Move to a separate backup folder to avoid confusion.
A13: 12 | B13: Info | C13: Domains without their own port-80 block | D13: Many HTTPS domains have no HTTP block. | E13: They fall to sites-enabled/default.conf (default_server), which redirects to HTTPS.
